<?xml version="1.0" ?>
<sdf version="1.6">
	<model name="myo_arm_small">
		<link name="static_link">
			<pose frame="">0.0 0.0 0.0 1.5707963267948966 -0.0 0.0</pose>
			<inertial>
				<pose frame="">0.0001131354427155749 0.04538460749026542 -1.500388376110969e-05 0 0 0</pose>
				<mass>22.287427485437306</mass>
				<inertia>
					<ixx>0.3587508996548991</ixx>
					<ixy>-0.0006165614742970186</ixy>
					<ixz>8.156253386987656e-05</ixz>
					<iyy>0.39743693844524036</iyy>
					<iyz>0.00019432462885518817</iyz>
					<izz>0.464460009230258</izz>
				</inertia>
			</inertial>
			<collision name="static_link_collision">
				<geometry>
					<mesh>
						<uri>model://myo_arm_small/meshes/static_link.stl</uri>
						<scale>0.001 0.001 0.001</scale>
					</mesh>
				</geometry>
			</collision>
			<visual name="static_link_visual">
				<geometry>
					<mesh>
						<uri>model://myo_arm_small/meshes/static_link.stl</uri>
						<scale>0.001 0.001 0.001</scale>
					</mesh>
				</geometry>
			</visual>
		</link>
		<link name="moving_link">
			<pose frame="">0.0 0.0 0.0 1.5707963267948966 -0.0 0.0</pose>
			<inertial>
				<pose frame="">-2.182096160333867e-05 0.5531020318685964 -1.5930014569144107e-05 0 0 0</pose>
				<mass>0.4297385541373958</mass>
				<inertia>
					<ixx>0.13873853376190265</ixx>
					<ixy>5.187240982798265e-06</ixy>
					<ixz>3.870329187521234e-06</ixz>
					<iyy>0.00010615273423563294</iyy>
					<iyz>-3.9843991705225996e-08</iyz>
					<izz>0.1387416296363018</izz>
				</inertia>
			</inertial>
			<collision name="moving_link_collision">
				<geometry>
					<mesh>
						<uri>model://myo_arm_small/meshes/moving_link.stl</uri>
						<scale>0.001 0.001 0.001</scale>
					</mesh>
				</geometry>
			</collision>
			<visual name="moving_link_visual">
				<geometry>
					<mesh>
						<uri>model://myo_arm_small/meshes/moving_link.stl</uri>
						<scale>0.001 0.001 0.001</scale>
					</mesh>
				</geometry>
			</visual>
		</link>
		
		
		<joint name="Rev1" type="revolute">
			<parent>moving_link</parent>
			<child>static_link</child>
			<pose frame="">-9.278560510240377e-18 1.4412976687738257e-17 0.018 0 0 0</pose>
			<axis>
				<xyz>0.0 0.0 -1.0</xyz>
				<limit>
					<lower>-1.5707963267948966</lower>
					<upper>1.5707963267948966</upper>
				</limit>
				<use_parent_model_frame>0</use_parent_model_frame>
			</axis>
		</joint>
	</model>
</sdf>
