<?xml version="1.0" ?>
<sdf version="1.6">
	<model name="myo_arm_small">
		<link name="static_link">
			<pose frame="">0.0 0.0 0.0 1.5707963267948966 -0.0 0.0</pose>
			<inertial>
				<pose frame="">-1.3525761252245432e-06 0.014056084136615113 -3.609806258698561e-07 0 0 0</pose>
				<mass>19.26602556190769</mass>
				<inertia>
					<ixx>0.16691690345589527</ixx>
					<ixy>7.976374268318868e-06</ixy>
					<ixz>1.2891552026846923e-06</ixz>
					<iyy>0.3926038296819974</iyy>
					<iyz>-2.1819968160974748e-09</iyz>
					<izz>0.2768182316304564</izz>
				</inertia>
			</inertial>
			<collision name="static_link_collision">
				<geometry>
					<mesh>
						<uri>model://myo_arm_small/meshes/static_link.stl</uri>
						<scale>0.001 0.001 0.001</scale>
					</mesh>
				</geometry>
			</collision>
			<visual name="static_link_visual">
				<geometry>
					<mesh>
						<uri>model://myo_arm_small/meshes/static_link.stl</uri>
						<scale>0.001 0.001 0.001</scale>
					</mesh>
				</geometry>
			</visual>
		</link>
		<link name="moving_link">
			<pose frame="">0.0 0.0 0.0 1.5707963267948966 -0.0 0.0</pose>
			<inertial>
				<pose frame="">-2.182096160333867e-05 0.5531020318685964 -1.5930014569144107e-05 0 0 0</pose>
				<mass>0.4297385541373958</mass>
				<inertia>
					<ixx>0.13873853376190265</ixx>
					<ixy>5.187240982798265e-06</ixy>
					<ixz>3.870329187521234e-06</ixz>
					<iyy>0.00010615273423563294</iyy>
					<iyz>-3.9843991705225996e-08</iyz>
					<izz>0.1387416296363018</izz>
				</inertia>
			</inertial>
			<collision name="moving_link_collision">
				<geometry>
					<mesh>
						<uri>model://myo_arm_small/meshes/moving_link.stl</uri>
						<scale>0.001 0.001 0.001</scale>
					</mesh>
				</geometry>
			</collision>
			<visual name="moving_link_visual">
				<geometry>
					<mesh>
						<uri>model://myo_arm_small/meshes/moving_link.stl</uri>
						<scale>0.001 0.001 0.001</scale>
					</mesh>
				</geometry>
			</visual>
		</link>
		<link name="RigidGroup1">
			<pose frame="">0.0 0.0 0.0 1.5707963267948966 -0.0 0.0</pose>
			<inertial>
				<pose frame="">-2.1069236703782783e-05 0.5659980046072518 -1.7104011713541975e-05 0 0 0</pose>
				<mass>0.39872535235307793</mass>
				<inertia>
					<ixx>0.13407927187739252</ixx>
					<ixy>4.754874776937723e-06</ixy>
					<ixz>3.8600085908408135e-06</ixz>
					<iyy>9.725386982064868e-05</iyy>
					<iyz>-1.0628189755779172e-10</iyz>
					<izz>0.1340791773029443</izz>
				</inertia>
			</inertial>
			<collision name="RigidGroup1_collision">
				<geometry>
					<mesh>
						<uri>model://myo_arm_small/meshes/RigidGroup1.stl</uri>
						<scale>0.001 0.001 0.001</scale>
					</mesh>
				</geometry>
			</collision>
			<visual name="RigidGroup1_visual">
				<geometry>
					<mesh>
						<uri>model://myo_arm_small/meshes/RigidGroup1.stl</uri>
						<scale>0.001 0.001 0.001</scale>
					</mesh>
				</geometry>
			</visual>
		</link>
		<joint name="Rev1" type="revolute">
			<parent>moving_link</parent>
			<child>static_link</child>
			<pose frame="">-9.278560510240377e-18 1.4412976687738257e-17 0.018 0 0 0</pose>
			<axis>
				<xyz>0.0 0.0 -1.0</xyz>
				<limit>
					<lower>-1.5707963267948966</lower>
					<upper>1.5707963267948966</upper>
				</limit>
				<use_parent_model_frame>0</use_parent_model_frame>
			</axis>
		</joint>
	</model>
</sdf>
